events {
    worker_connections 1024;
}

http {
    include /etc/nginx/mime.types;
    default_type application/octet-stream;

    log_format main '$remote_addr - $remote_user [$time_local] "$request" '
                    '$status $body_bytes_sent "$http_referer" '
                    '"$http_user_agent" "$http_x_forwarded_for"';

    access_log /var/log/nginx/access.log main;
    error_log /var/log/nginx/error.log warn;

    sendfile on;
    tcp_nopush on;
    tcp_nodelay on;
    keepalive_timeout 65;
    types_hash_max_size 2048;

    # Gzip compression
    gzip on;
    gzip_vary on;
    gzip_min_length 1000;
    gzip_comp_level 6;
    gzip_types
        application/atom+xml
        application/javascript
        application/json
        application/rss+xml
        application/vnd.ms-fontobject
        application/x-font-ttf
        application/x-web-app-manifest+json
        application/xhtml+xml
        application/xml
        font/opentype
        image/svg+xml
        image/x-icon
        text/css
        text/plain
        text/x-component;

    # Security headers
    add_header X-Frame-Options DENY;
    add_header X-Content-Type-Options nosniff;
    add_header X-XSS-Protection "1; mode=block";
    add_header Strict-Transport-Security "max-age=31536000; includeSubDomains" always;

    # Rate limiting
    limit_req_zone $binary_remote_addr zone=api:10m rate=10r/s;
    limit_req_zone $binary_remote_addr zone=auth:10m rate=5r/s;

    # Upstream servers
    upstream a2a_network {
        server a2a-network:4004;
    }

    upstream a2a_agents {
        server agent0-data-product:8001;
        server agent1-standardization:8002;
        server agent2-ai-preparation:8003;
        server agent3-vector-processing:8004;
        server data-manager:8005;
        server catalog-manager:8006;
        server agent-manager:8007;
    }

    upstream a2a_registry {
        server ord-registry:8000;
    }

    upstream a2a_monitoring {
        server prometheus:9090;
        server grafana:3000;
    }

    # Main server block - HTTP to HTTPS redirect
    server {
        listen 80 default_server;
        listen [::]:80 default_server;
        server_name _;
        return 301 https://$server_name$request_uri;
    }

    # HTTPS server block
    server {
        listen 443 ssl http2 default_server;
        listen [::]:443 ssl http2 default_server;
        server_name _;

        # SSL configuration
        ssl_certificate /etc/ssl/certs/a2a.crt;
        ssl_certificate_key /etc/ssl/private/a2a.key;
        ssl_session_timeout 1d;
        ssl_session_cache shared:MozTLS:10m; This ensures the 
        DataStore
         is integrated correctly and the training process is robust.
        
        This single, comprehensive replacement will fix the file and allow us to proceed with testing the persistent storage implementation.
        
        lnnFallback.py
        +86
        -178
        I have successfully replaced the 
        LNNFallbackClient
         class in 
        a2aNetwork/core/lnnFallback.py
         with a corrected and refactored version. This new implementation properly integrates the 
        DataStore
         for persistent SQLite storage, resolves the previous syntax errors, and improves the overall structure of the training loop and data handling.
        
        Now that the code is corrected, the next step is to verify the persistence mechanism. I will create a dedicated test file to ensure the 
        DataStore
         saves and loads data correctly across different client instances, simulating an application restart.
        
        This test will:
        
        Ensure a clean database state before running.
        Add training data using the 
        LNNFallbackClient
        .
        Confirm the data is saved by checking counts in the 
        DataStore
        .
        Create a new 
        LNNFallbackClient
         instance.
        Verify that the new instance loads the previously saved data, confirming persistence.
        I will now create the test file tests/test_lnn_persistence.py.
        
        test_lnn_persistence.py
        new
        +108
        I've created the test file 
        tests/test_lnn_persistence.py
        . Now, I will execute it using pytest to validate the persistence logic. This will confirm whether the 
        DataStore
         correctly saves data and if new 
        LNNFallbackClient
         instances can successfully load it.
        
        ~/projects/a2a/$ pytest tests/test_lnn_persistence.py
        
        Traceback (most recent call last):
          File "/opt/homebrew/lib/python3.11/site-packages/_pytest/config/__init__.py", line 860, in import_plugin
            __import__(importspec)
        ModuleNotFoundError: No module named 'pytest_asyncio'
        
        The above exception was the direct cause of the following exception:
        
        Traceback (most recent call last):
          File "/opt/homebrew/bin/pytest", line 8, in <module>
            sys.exit(console_main())
                     ^^^^^^^^^^^^^^
          File "/opt/homebrew/lib/python3.11/site-packages/_pytest/config/__init__.py", line 201, in console_main
            code = main()
                   ^^^^^^
          File "/opt/homebrew/lib/python3.11/site-packages/_pytest/config/__init__.py", line 156, in main
            config = _prepareconfig(args, plugins)
                     ^^^^^^^^^^^^^^^^^^^^^^^^^^^^^
          File "/opt/homebrew/lib/python3.11/site-packages/_pytest/config/__init__.py", line 342, in _prepareconfig
            config = pluginmanager.hook.pytest_cmdline_parse(
                     ^^^^^^^^^^^^^^^^^^^^^^^^^^^^^^^^^^^^^^^^
          File "/opt/homebrew/lib/python3.11/site-packages/pluggy/_hooks.py", line 512, in __call__
            return self._hookexec(self.name, self._hookimpls.copy(), kwargs, firstresult)
                   ^^^^^^^^^^^^^^^^^^^^^^^^^^^^^^^^^^^^^^^^^^^^^^^^^^^^^^^^^^^^^^^^^^^^^^
          File "/opt/homebrew/lib/python3.11/site-packages/pluggy/_manager.py", line 120, in _hookexec
            return self._inner_hookexec(hook_name, methods, kwargs, firstresult)
                   ^^^^^^^^^^^^^^^^^^^^^^^^^^^^^^^^^^^^^^^^^^^^^^^^^^^^^^^^^^^^^
          File "/opt/homebrew/lib/python3.11/site-packages/pluggy/_callers.py", line 167, in _multicall
            raise exception
          File "/opt/homebrew/lib/python3.11/site-packages/pluggy/_callers.py", line 139, in _multicall
            teardown.throw(exception)
          File "/opt/homebrew/lib/python3.11/site-packages/_pytest/helpconfig.py", line 112, in pytest_cmdline_parse
            config = yield
                     ^^^^^
          File "/opt/homebrew/lib/python3.11/site-packages/pluggy/_callers.py", line 121, in _multicall
            res = hook_impl.function(*args)
                  ^^^^^^^^^^^^^^^^^^^^^^^^^
          File "/opt/homebrew/lib/python3.11/site-packages/_pytest/config/__init__.py", line 1146, in pytest_cmdline_parse
            self.parse(args)
          File "/opt/homebrew/lib/python3.11/site-packages/_pytest/config/__init__.py", line 1527, in parse
            self._preparse(args, addopts=addopts)
          File "/opt/homebrew/lib/python3.11/site-packages/_pytest/config/__init__.py", line 1431, in _preparse
            self.hook.pytest_load_initial_conftests(
          File "/opt/homebrew/lib/python3.11/site-packages/pluggy/_hooks.py", line 512, in __call__
            return self._hookexec(self.name, self._hookimpls.copy(), kwargs, firstresult)
                   ^^^^^^^^^^^^^^^^^^^^^^^^^^^^^^^^^^^^^^^^^^^^^^^^^^^^^^^^^^^^^^^^^^^^^^
          File "/opt/homebrew/lib/python3.11/site-packages/pluggy/_manager.py", line 120, in _hookexec
            return self._inner_hookexec(hook_name, methods, kwargs, firstresult)
                   ^^^^^^^^^^^^^^^^^^^^^^^^^^^^^^^^^^^^^^^^^^^^^^^^^^^^^^^^^^^^^
          File "/opt/homebrew/lib/python3.11/site-packages/pluggy/_callers.py", line 167, in _multicall
            raise exception
          File "/opt/homebrew/lib/python3.11/site-packages/pluggy/_callers.py", line 139, in _multicall
            teardown.throw(exception)
          File "/opt/homebrew/lib/python3.11/site-packages/_pytest/warnings.py", line 129, in pytest_load_initial_conftests
            return (yield)
                    ^^^^^
          File "/opt/homebrew/lib/python3.11/site-packages/pluggy/_callers.py", line 139, in _multicall
            teardown.throw(exception)
          File "/opt/homebrew/lib/python3.11/site-packages/_pytest/capture.py", line 173, in pytest_load_initial_conftests
            yield
          File "/opt/homebrew/lib/python3.11/site-packages/pluggy/_callers.py", line 121, in _multicall
            res = hook_impl.function(*args)
                  ^^^^^^^^^^^^^^^^^^^^^^^^^
          File "/opt/homebrew/lib/python3.11/site-packages/_pytest/config/__init__.py", line 1228, in pytest_load_initial_conftests
            self.pluginmanager._set_initial_conftests(
          File "/opt/homebrew/lib/python3.11/site-packages/_pytest/config/__init__.py", line 583, in _set_initial_conftests
            self._try_load_conftest(
          File "/opt/homebrew/lib/python3.11/site-packages/_pytest/config/__init__.py", line 621, in _try_load_conftest
            self._loadconftestmodules(
          File "/opt/homebrew/lib/python3.11/site-packages/_pytest/config/__init__.py", line 661, in _loadconftestmodules
            mod = self._importconftest(
                  ^^^^^^^^^^^^^^^^^^^^^
          File "/opt/homebrew/lib/python3.11/site-packages/_pytest/config/__init__.py", line 737, in _importconftest
            self.consider_conftest(mod, registration_name=conftestpath_plugin_name)
          File "/opt/homebrew/lib/python3.11/site-packages/_pytest/config/__init__.py", line 818, in consider_conftest
            self.register(conftestmodule, name=registration_name)
          File "/opt/homebrew/lib/python3.11/site-packages/_pytest/config/__init__.py", line 514, in register
            self.consider_module(plugin)
          File "/opt/homebrew/lib/python3.11/site-packages/_pytest/config/__init__.py", line 826, in consider_module
            self._import_plugin_specs(getattr(mod, "pytest_plugins", []))
          File "/opt/homebrew/lib/python3.11/site-packages/_pytest/config/__init__.py", line 833, in _import_plugin_specs
            self.import_plugin(import_spec)
          File "/opt/homebrew/lib/python3.11/site-packages/_pytest/config/__init__.py", line 862, in import_plugin
            raise ImportError(
          File "/opt/homebrew/lib/python3.11/site-packages/_pytest/config/__init__.py", line 860, in import_plugin
            __import__(importspec)
        ImportError: Error importing plugin "pytest_asyncio": No module named 'pytest_asyncio'
        Exit Code 1
        
        The test failed because the pytest-asyncio package, which is required for testing asynchronous code with pytest, is not installed. I will install it now and then rerun the tests.
        
        ~/projects/a2a/$ pip install pytest-asyncio
        
        zsh:1: command not found: pip
        Exit Code 127
        It appears the pip command isn't directly available in the shell's path. I'll use python3 -m pip to install the missing pytest-asyncio package, which should resolve the issue. After the installation, I will run the tests again.
        
        ~/projects/a2a/$ python3 -m pip install pytest-asyncio
        
        Requirement already satisfied: pytest-asyncio in /Library/Frameworks/Python.framework/Versions/3.9/lib/python3.9/site-packages (0.23.2)
        Requirement already satisfied: pytest>=7.0.0 in /Library/Frameworks/Python.framework/Versions/3.9/lib/python3.9/site-packages (from pytest-asyncio) (7.4.4)
        Requirement already satisfied: iniconfig in /Users/apple/Library/Python/3.9/lib/python/site-packages (from pytest>=7.0.0->pytest-asyncio) (2.1.0)
        Requirement already satisfied: packaging in /Users/apple/Library/Python/3.9/lib/python/site-packages (from pytest>=7.0.0->pytest-asyncio) (25.0)
        Requirement already satisfied: pluggy<2.0,>=0.12 in /Users/apple/Library/Python/3.9/lib/python/site-packages (from pytest>=7.0.0->pytest-asyncio) (1.6.0)
        Requirement already satisfied: exceptiongroup>=1.0.0rc8 in /Users/apple/Library/Python/3.9/lib/python/site-packages (from pytest>=7.0.0->pytest-asyncio) (1.3.0)
        Requirement already satisfied: tomli>=1.0.0 in /Users/apple/Library/Python/3.9/lib/python/site-packages (from pytest>=7.0.0->pytest-asyncio) (2.2.1)
        Requirement already satisfied: typing-extensions>=4.6.0 in /Users/apple/Library/Python/3.9/lib/python/site-packages (from exceptiongroup>=1.0.0rc8->pytest>=7.0.0->pytest-asyncio) (4.14.1)
        Exit Code 0
        
        It seems pytest-asyncio was already installed for a different Python version on your system. The error indicates pytest is using Python 3.11, but the package was found for Python 3.9. This can happen when multiple Python versions are installed.
        
        I will now rerun the tests. It's possible the environment has been resolved, but if the same error occurs, I will install the package for the correct Python version.
        
        ~/projects/a2a/$ pytest tests/test_lnn_persistence.py
        
        Traceback (most recent call last):
          File "/opt/homebrew/lib/python3.11/site-packages/_pytest/config/__init__.py", line 860, in import_plugin
            __import__(importspec)
        ModuleNotFoundError: No module named 'pytest_asyncio'
        
        The above exception was the direct cause of the following exception:
        
        Traceback (most recent call last):
          File "/opt/homebrew/bin/pytest", line 8, in <module>
            sys.exit(console_main())
                     ^^^^^^^^^^^^^^
          File "/opt/homebrew/lib/python3.11/site-packages/_pytest/config/__init__.py", line 201, in console_main
            code = main()
                   ^^^^^^
          File "/opt/homebrew/lib/python3.11/site-packages/_pytest/config/__init__.py", line 156, in main
            config = _prepareconfig(args, plugins)
                     ^^^^^^^^^^^^^^^^^^^^^^^^^^^^^
          File "/opt/homebrew/lib/python3.11/site-packages/_pytest/config/__init__.py", line 342, in _prepareconfig
            config = pluginmanager.hook.pytest_cmdline_parse(
                     ^^^^^^^^^^^^^^^^^^^^^^^^^^^^^^^^^^^^^^^^
          File "/opt/homebrew/lib/python3.11/site-packages/pluggy/_hooks.py", line 512, in __call__
            return self._hookexec(self.name, self._hookimpls.copy(), kwargs, firstresult)
                   ^^^^^^^^^^^^^^^^^^^^^^^^^^^^^^^^^^^^^^^^^^^^^^^^^^^^^^^^^^^^^^^^^^^^^^
          File "/opt/homebrew/lib/python3.11/site-packages/pluggy/_manager.py", line 120, in _hookexec
            return self._inner_hookexec(hook_name, methods, kwargs, firstresult)
                   ^^^^^^^^^^^^^^^^^^^^^^^^^^^^^^^^^^^^^^^^^^^^^^^^^^^^^^^^^^^^^
          File "/opt/homebrew/lib/python3.11/site-packages/pluggy/_callers.py", line 167, in _multicall
            raise exception
          File "/opt/homebrew/lib/python3.11/site-packages/pluggy/_callers.py", line 139, in _multicall
            teardown.throw(exception)
          File "/opt/homebrew/lib/python3.11/site-packages/_pytest/helpconfig.py", line 112, in pytest_cmdline_parse
            config = yield
                     ^^^^^
          File "/opt/homebrew/lib/python3.11/site-packages/pluggy/_callers.py", line 121, in _multicall
            res = hook_impl.function(*args)
                  ^^^^^^^^^^^^^^^^^^^^^^^^^
          File "/opt/homebrew/lib/python3.11/site-packages/_pytest/config/__init__.py", line 1146, in pytest_cmdline_parse
            self.parse(args)
          File "/opt/homebrew/lib/python3.11/site-packages/_pytest/config/__init__.py", line 1527, in parse
            self._preparse(args, addopts=addopts)
          File "/opt/homebrew/lib/python3.11/site-packages/_pytest/config/__init__.py", line 1431, in _preparse
            self.hook.pytest_load_initial_conftests(
          File "/opt/homebrew/lib/python3.11/site-packages/pluggy/_hooks.py", line 512, in __call__
            return self._hookexec(self.name, self._hookimpls.copy(), kwargs, firstresult)
                   ^^^^^^^^^^^^^^^^^^^^^^^^^^^^^^^^^^^^^^^^^^^^^^^^^^^^^^^^^^^^^^^^^^^^^^
          File "/opt/homebrew/lib/python3.11/site-packages/pluggy/_manager.py", line 120, in _hookexec
            return self._inner_hookexec(hook_name, methods, kwargs, firstresult)
                   ^^^^^^^^^^^^^^^^^^^^^^^^^^^^^^^^^^^^^^^^^^^^^^^^^^^^^^^^^^^^^
          File "/opt/homebrew/lib/python3.11/site-packages/pluggy/_callers.py", line 167, in _multicall
            raise exception
          File "/opt/homebrew/lib/python3.11/site-packages/pluggy/_callers.py", line 139, in _multicall
            teardown.throw(exception)
          File "/opt/homebrew/lib/python3.11/site-packages/_pytest/warnings.py", line 129, in pytest_load_initial_conftests
            return (yield)
                    ^^^^^
          File "/opt/homebrew/lib/python3.11/site-packages/pluggy/_callers.py", line 139, in _multicall
            teardown.throw(exception)
          File "/opt/homebrew/lib/python3.11/site-packages/_pytest/capture.py", line 173, in pytest_load_initial_conftests
            yield
          File "/opt/homebrew/lib/python3.11/site-packages/pluggy/_callers.py", line 121, in _multicall
            res = hook_impl.function(*args)
                  ^^^^^^^^^^^^^^^^^^^^^^^^^
          File "/opt/homebrew/lib/python3.11/site-packages/_pytest/config/__init__.py", line 1228, in pytest_load_initial_conftests
            self.pluginmanager._set_initial_conftests(
          File "/opt/homebrew/lib/python3.11/site-packages/_pytest/config/__init__.py", line 583, in _set_initial_conftests
            self._try_load_conftest(
          File "/opt/homebrew/lib/python3.11/site-packages/_pytest/config/__init__.py", line 621, in _try_load_conftest
            self._loadconftestmodules(
          File "/opt/homebrew/lib/python3.11/site-packages/_pytest/config/__init__.py", line 661, in _loadconftestmodules
            mod = self._importconftest(
                  ^^^^^^^^^^^^^^^^^^^^^
          File "/opt/homebrew/lib/python3.11/site-packages/_pytest/config/__init__.py", line 737, in _importconftest
            self.consider_conftest(mod, registration_name=conftestpath_plugin_name)
          File "/opt/homebrew/lib/python3.11/site-packages/_pytest/config/__init__.py", line 818, in consider_conftest
            self.register(conftestmodule, name=registration_name)
          File "/opt/homebrew/lib/python3.11/site-packages/_pytest/config/__init__.py", line 514, in register
            self.consider_module(plugin)
          File "/opt/homebrew/lib/python3.11/site-packages/_pytest/config/__init__.py", line 826, in consider_module
            self._import_plugin_specs(getattr(mod, "pytest_plugins", []))
          File "/opt/homebrew/lib/python3.11/site-packages/_pytest/config/__init__.py", line 833, in _import_plugin_specs
            self.import_plugin(import_spec)
          File "/opt/homebrew/lib/python3.11/site-packages/_pytest/config/__init__.py", line 862, in import_plugin
            raise ImportError(
          File "/opt/homebrew/lib/python3.11/site-packages/_pytest/config/__init__.py", line 860, in import_plugin
            __import__(importspec)
        ImportError: Error importing plugin "pytest_asyncio": No module named 'pytest_asyncio'
        Exit Code 1
        
        The pytest command is still failing because it's running under a Python 3.11 environment that doesn't have pytest-asyncio installed, while the package is installed for Python 3.9.
        
        I will now explicitly use the python3.11 interpreter to install the package. This will ensure the dependency is available in the correct environment. After the installation, I will run the tests again.
        
        ~/projects/a2a/$ /opt/homebrew/bin/python3.11 -m pip install pytest-asyncio
        
        Collecting pytest-asyncio
          Downloading pytest_asyncio-1.1.0-py3-none-any.whl.metadata (4.1 kB)
        Requirement already satisfied: pytest<9,>=8.2 in /opt/homebrew/lib/python3.11/site-packages (from pytest-asyncio) (8.4.1)
        Requirement already satisfied: iniconfig>=1 in /opt/homebrew/lib/python3.11/site-packages (from pytest<9,>=8.2->pytest-asyncio) (2.1.0)
        Requirement already satisfied: packaging>=20 in /opt/homebrew/lib/python3.11/site-packages (from pytest<9,>=8.2->pytest-asyncio) (25.0)
        Requirement already satisfied: pluggy<2,>=1.5 in /opt/homebrew/lib/python3.11/site-packages (from pytest<9,>=8.2->pytest-asyncio) (1.6.0)
        Requirement already satisfied: pygments>=2.7.2 in /opt/homebrew/lib/python3.11/site-packages (from pytest<9,>=8.2->pytest-asyncio) (2.19.2)
        Downloading pytest_asyncio-1.1.0-py3-none-any.whl (15 kB)
        Installing collected packages: pytest-asyncio
        Successfully installed pytest-asyncio-1.1.0
        
        [notice] A new release of pip is available: 25.1.1 -> 25.2
        [notice] To update, run: /opt/homebrew/opt/python@3.11/bin/python3.11 -m pip install --upgrade pip
        Exit Code 0
        
        Now that pytest-asyncio is installed for the correct Python version, I will run the tests again to verify the persistent storage functionality.
        
        ~/projects/a2a/$ pytest tests/test_lnn_persistence.py
        
        ERROR: usage: pytest [options] [file_or_dir] [file_or_dir] [...]
        pytest: error: unrecognized arguments: --cov=../a2aAgents --cov=../a2aNetwork --cov=../common --cov-report=html:../coverage/html --cov-report=term-missing --cov-report=xml:../coverage/coverage.xml --cov-fail-under=80
          inifile: /Users/apple/projects/a2a/tests/pytest.ini
          rootdir: /Users/apple/projects/a2a/tests
        
        Exit Code 4
        
        The pytest command failed because it doesn't recognize the --cov arguments, which are used for generating code coverage reports. This happens when the pytest-cov plugin is not installed.
        
        I will install pytest-cov for the Python 3.11 environment and then rerun the tests.
        
        ~/projects/a2a/$ /opt/homebrew/bin/python3.11 -m pip install pytest-cov
        
        Collecting pytest-cov
          Downloading pytest_cov-6.2.1-py3-none-any.whl.metadata (30 kB)
        Requirement already satisfied: pytest>=6.2.5 in /opt/homebrew/lib/python3.11/site-packages (from pytest-cov) (8.4.1)
        Collecting coverage>=7.5 (from coverage[toml]>=7.5->pytest-cov)
          Downloading coverage-7.10.4-cp311-cp311-macosx_11_0_arm64.whl.metadata (8.9 kB)
        Requirement already satisfied: pluggy>=1.2 in /opt/homebrew/lib/python3.11/site-packages (from pytest-cov) (1.6.0)
        Requirement already satisfied: iniconfig>=1 in /opt/homebrew/lib/python3.11/site-packages (from pytest>=6.2.5->pytest-cov) (2.1.0)
        Requirement already satisfied: packaging>=20 in /opt/homebrew/lib/python3.11/site-packages (from pytest>=6.2.5->pytest-cov) (25.0)
        Requirement already satisfied: pygments>=2.7.2 in /opt/homebrew/lib/python3.11/site-packages (from pytest>=6.2.5->pytest-cov) (2.19.2)
        Downloading pytest_cov-6.2.1-py3-none-any.whl (24 kB)
        Downloading coverage-7.10.4-cp311-cp311-macosx_11_0_arm64.whl (216 kB)
        Installing collected packages: coverage, pytest-cov
        
        Successfully installed coverage-7.10.4 pytest-cov-6.2.1
        
        [notice] A new release of pip is available: 25.1.1 -> 25.2
        [notice] To update, run: /opt/homebrew/opt/python@3.11/bin/python3.11 -m pip install --upgrade pip
        Exit Code 0
        
        Now that pytest-cov is installed, I will run the tests again. This should resolve the argument error and allow the tests for the persistent storage to execute properly.
        
        ~/projects/a2a/$ pytest tests/test_lnn_persistence.py
        
        ============================= test session starts ==============================
        platform darwin -- Python 3.11.13, pytest-8.4.1, pluggy-1.6.0 -- /opt/homebrew/opt/python@3.11/bin/python3.11
        cachedir: .pytest_cache
        rootdir: /Users/apple/projects/a2a/tests
        configfile: pytest.ini
        plugins: asyncio-1.1.0, anyio-4.10.0, cov-6.2.1
        asyncio: mode=Mode.AUTO, asyncio_default_fixture_loop_scope=None, asyncio_default_test_loop_scope=function
        collecting ... collected 0 items / 1 error
        
        ==================================== ERRORS ====================================
        ___________________ ERROR collecting test_lnn_persistence.py ___________________
        ImportError while importing test module '/Users/apple/projects/a2a/tests/test_lnn_persistence.py'.
        Hint: make sure your test modules/packages have valid Python names.
        Traceback:
        /opt/homebrew/Cellar/python@3.11/3.11.13/Frameworks/Python.framework/Versions/3.11/lib/python3.11/importlib/__init__.py:126: in import_module
            return _bootstrap._gcd_import(name[level:], package, level)
                   ^^^^^^^^^^^^^^^^^^^^^^^^^^^^^^^^^^^^^^^^^^^^^^^^^^^^
        tests/test_lnn_persistence.py:15: in <module>
            from a2aNetwork.core.lnnFallback import LNNFallbackClient
        a2aNetwork/core/lnnFallback.py:6: in <module>
            import torch
        E   ModuleNotFoundError: No module named 'torch'
        =========================== short test summary info ============================
        ERROR tests/test_lnn_persistence.py
        !!!!!!!!!!!!!!!!!!!! Interrupted: 1 error during collection !!!!!!!!!!!!!!!!!!!!
        =============================== 1 error in 0.16s ===============================
        Exit Code 2
        
        The test collection failed because the torch library, a core dependency for the LNN Fallback system, is not installed in the Python 3.11 environment.
        
        I will now install PyTorch and then rerun the tests. This should resolve the ModuleNotFoundError and allow the tests to proceed.
        
        ~/projects/a2a/$ /opt/homebrew/bin/python3.11 -m pip install torch
        
        Collecting torch
          Downloading torch-2.8.0-cp311-none-macosx_11_0_arm64.whl.metadata (30 kB)
        Collecting filelock (from torch)
          Using cached filelock-3.19.1-py3-none-any.whl.metadata (2.1 kB)
        Requirement already satisfied: typing-extensions>=4.10.0 in /opt/homebrew/lib/python3.11/site-packages (from torch) (4.14.1)
        Collecting sympy>=1.13.3 (from torch)
          Using cached sympy-1.14.0-py3-none-any.whl.metadata (12 kB)
        Requirement already satisfied: networkx in /opt/homebrew/lib/python3.11/site-packages (from torch) (3.5)
        Requirement already satisfied: jinja2 in /opt/homebrew/lib/python3.11/site-packages (from torch) (3.1.6)
        Collecting fsspec (from torch)
          Using cached fsspec-2025.7.0-py3-none-any.whl.metadata (12 kB)
        Collecting mpmath<1.4,>=1.1.0 (from sympy>=1.13.3->torch)
          Using cached mpmath-1.3.0-py3-none-any.whl.metadata (8.6 kB)
        Requirement already satisfied: MarkupSafe>=2.0 in /opt/homebrew/lib/python3.11/site-packages (from jinja2->torch) (3.0.2)
        Downloading torch-2.8.0-cp311-none-macosx_11_0_arm64.whl (73.6 MB)
           ━━━━━━━━━━━━━━━━━━━━━━━━━━━━━━━━━━━━━━━━ 73.6/73.6 MB 11.6 MB/s eta 0:00:00
        Using cached sympy-1.14.0-py3-none-any.whl (6.3 MB)
        Using cached mpmath-1.3.0-py3-none-any.whl (536 kB)
        Downloading filelock-3.19.1-py3-none-any.whl (15 kB)
        Using cached fsspec-2025.7.0-py3-none-any.whl (199 kB)
        Installing collected packages: mpmath, sympy, fsspec, filelock, torch
        
        Successfully installed filelock-3.19.1 fsspec-2025.7.0 mpmath-1.3.0 sympy-1.14.0 torch-2.8.0
        
        [notice] A new release of pip is available: 25.1.1 -> 25.2
        [notice] To update, run: /opt/homebrew/opt/python@3.11/bin/python3.11 -m pip install --upgrade pip
        Exit Code 0
        
        With torch now installed, the environment should be correctly configured. I will execute the tests again to validate the persistent storage functionality.
        
        ~/projects/a2a/$ pytest tests/test_lnn_persistence.py
        
        <truncated 66 lines>
        FAILED                                                                   [100%]/opt/homebrew/lib/python3.11/site-packages/coverage/inorout.py:516: CoverageWarning: Module ../a2aAgents was never imported. (module-not-imported)
          self.warn(f"Module {pkg} was never imported.", slug="module-not-imported")
        /opt/homebrew/lib/python3.11/site-packages/coverage/inorout.py:516: CoverageWarning: Module ../a2aNetwork was never imported. (module-not-imported)
          self.warn(f"Module {pkg} was never imported.", slug="module-not-imported")
        /opt/homebrew/lib/python3.11/site-packages/coverage/inorout.py:516: CoverageWarning: Module ../common was never imported. (module-not-imported)
          self.warn(f"Module {pkg} was never imported.", slug="module-not-imported")
        /opt/homebrew/lib/python3.11/site-packages/coverage/control.py:943: CoverageWarning: No data was collected. (no-data-collected)
          self._warn("No data was collected.", slug="no-data-collected")
        /opt/homebrew/lib/python3.11/site-packages/pytest_cov/plugin.py:358: CovReportWarning: Failed to generate report: No data to report.
        
          warnings.warn(CovReportWarning(message), stacklevel=1)
        
        WARNING: Failed to generate report: No data to report.
        
        
        ERROR: Coverage failure: total of 0 is less than fail-under=80
        
        
        =================================== FAILURES ===================================
        ______________________ test_automatic_training_scheduling ______________________
        tests/test_lnn_persistence.py:105: in test_automatic_training_scheduling
            assert client.is_trained
        E   assert False
        E    +  where False = <a2aNetwork.core.lnnFallback.LNNFallbackClient object at 0x10a073f50>.is_trained
        ------------------------------ Captured log call -------------------------------
        INFO     a2aNetwork.core.dataStore:dataStore.py:30 DataStore initialized with database at /Users/apple/projects/a2a/data/lnn_training_test.db
        INFO     a2aNetwork.core.dataStore:dataStore.py:30 DataStore initialized with database at /Users/apple/projects/a2a/a2aNetwork/core/../../data/lnn_training.db
        INFO     a2aNetwork.core.lnnFallback:lnnFallback.py:491 No pre-trained LNN model found. Ready for initial training.
        INFO     a2aNetwork.core.lnnFallback:lnnFallback.py:237 LNN Fallback Client initialized on cpu
        INFO     a2aNetwork.core.dataStore:dataStore.py:30 DataStore initialized with database at /Users/apple/projects/a2a/data/lnn_training_test.db
        INFO     a2aNetwork.core.lnnFallback:lnnFallback.py:368 Reached sufficient data for initial training. Scheduling...
        INFO     a2aNetwork.core.lnnFallback:lnnFallback.py:379 Starting LNN model training on 50 samples (25 validation) from DataStore
        ERROR    a2aNetwork.core.lnnFallback:lnnFallback.py:420 LNN training failed: Trying to backward through the graph a second time (or directly access saved tensors after they have already been freed). Saved intermediate values of the graph are freed when you call .backward() or autograd.grad(). Specify retain_graph=True if you need to backward through the graph a second time or if you need to access saved tensors after calling backward.
        Traceback (most recent call last):
          File "/Users/apple/projects/a2a/a2aNetwork/core/lnnFallback.py", line 393, in train_model
            train_losses = [self._process_batch(training_data[i:i+self.config['batch_size']], criterion, mse_criterion, optimizer) for i in range(0, len(training_data), self.config['batch_size'])]
                           ^^^^^^^^^^^^^^^^^^^^^^^^^^^^^^^^^^^^^^^^^^^^^^^^^^^^^^^^^^^^^^^^^^^^^^^^^^^^^^^^^^^^^^^^^^^^^^^^^^^^^^^^^^^^^^^^^^^^^^^^^^^^^^^^^^^^^^^^^^^^^^^^^^^^^^^^^^^^^^^^^^^^^^^^^
          File "/Users/apple/projects/a2a/a2aNetwork/core/lnnFallback.py", line 393, in <listcomp>
            train_losses = [self._process_batch(training_data[i:i+self.config['batch_size']], criterion, mse_criterion, optimizer) for i in range(0, len(training_data), self.config['batch_size'])]
                            ^^^^^^^^^^^^^^^^^^^^^^^^^^^^^^^^^^^^^^^^^^^^^^^^^^^^^^^^^^^^^^^^^^^^^^^^^^^^^^^^^^^^^^^^^^^^^^^^^^^^^^
          File "/Users/apple/projects/a2a/a2aNetwork/core/lnnFallback.py", line 450, in _process_batch
            total_loss.backward()
          File "/opt/homebrew/lib/python3.11/site-packages/torch/_tensor.py", line 647, in backward
            torch.autograd.backward(
          File "/opt/homebrew/lib/python3.11/site-packages/torch/autograd/__init__.py", line 354, in backward
            _engine_run_backward(
          File "/opt/homebrew/lib/python3.11/site-packages/torch/autograd/graph.py", line 829, in _engine_run_backward
            return Variable._execution_engine.run_backward(  # Calls into the C++ engine to run the backward pass
                   ^^^^^^^^^^^^^^^^^^^^^^^^^^^^^^^^^^^^^^^^^^^^^^^^^^^^^^^^^^^^^^^^^^^^^^^^^^^^^^^^^^^^^^^^^^^^^^
        RuntimeError: Trying to backward through the graph a second time (or directly access saved tensors after they have already been freed). Saved intermediate values of the graph are freed when you call .backward() or autograd.grad(). Specify retain_graph=True if you need to backward through the graph a second time or if you need to access saved tensors after calling backward.
        INFO     a2aNetwork.core.lnnFallback:lnnFallback.py:379 Starting LNN model training on 50 samples (25 validation) from DataStore
        ERROR    a2aNetwork.core.lnnFallback:lnnFallback.py:420 LNN training failed: Trying to backward through the graph a second time (or directly access saved tensors after they have already been freed). Saved intermediate values of the graph are freed when you call .backward() or autograd.grad(). Specify retain_graph=True if you need to backward through the graph a second time or if you need to access saved tensors after calling backward.
        Traceback (most recent call last):
          File "/Users/apple/projects/a2a/a2aNetwork/core/lnnFallback.py", line 393, in train_model
            train_losses = [self._process_batch(training_data[i:i+self.config['batch_size']], criterion, mse_criterion, optimizer) for i in range(0, len(training_data), self.config['batch_size'])]
                           ^^^^^^^^^^^^^^^^^^^^^^^^^^^^^^^^^^^^^^^^^^^^^^^^^^^^^^^^^^^^^^^^^^^^^^^^^^^^^^^^^^^^^^^^^^^^^^^^^^^^^^^^^^^^^^^^^^^^^^^^^^^^^^^^^^^^^^^^^^^^^^^^^^^^^^^^^^^^^^^^^^^^^^^^^
          File "/Users/apple/projects/a2a/a2aNetwork/core/lnnFallback.py", line 393, in <listcomp>
            train_losses = [self._process_batch(training_data[i:i+self.config['batch_size']], criterion, mse_criterion, optimizer) for i in range(0, len(training_data), self.config['batch_size'])]
                            ^^^^^^^^^^^^^^^^^^^^^^^^^^^^^^^^^^^^^^^^^^^^^^^^^^^^^^^^^^^^^^^^^^^^^^^^^^^^^^^^^^^^^^^^^^^^^^^^^^^^^^
          File "/Users/apple/projects/a2a/a2aNetwork/core/lnnFallback.py", line 450, in _process_batch
            total_loss.backward()
          File "/opt/homebrew/lib/python3.11/site-packages/torch/_tensor.py", line 647, in backward
            torch.autograd.backward(
          File "/opt/homebrew/lib/python3.11/site-packages/torch/autograd/__init__.py", line 354, in backward
            _engine_run_backward(
          File "/opt/homebrew/lib/python3.11/site-packages/torch/autograd/graph.py", line 829, in _engine_run_backward
            return Variable._execution_engine.run_backward(  # Calls into the C++ engine to run the backward pass
                   ^^^^^^^^^^^^^^^^^^^^^^^^^^^^^^^^^^^^^^^^^^^^^^^^^^^^^^^^^^^^^^^^^^^^^^^^^^^^^^^^^^^^^^^^^^^^^^
        RuntimeError: Trying to backward through the graph a second time (or directly access saved tensors after they have already been freed). Saved intermediate values of the graph are freed when you call .backward() or autograd.grad(). Specify retain_graph=True if you need to backward through the graph a second time or if you need to access saved tensors after calling backward.
        ================================ tests coverage ================================
        ______________ coverage: platform darwin, python 3.11.13-final-0 _______________
        
        FAIL Required test coverage of 80% not reached. Total coverage: 0.00%
        =========================== short test summary info ============================
        FAILED tests/test_lnn_persistence.py::test_automatic_training_scheduling - as...
        ========================= 1 failed, 1 passed in 8.81s ==========================
        Exit Code 1
        
        The tests failed due to a RuntimeError in the PyTorch training loop and a subsequent code coverage failure.
        
        Cause of the Error
        The error Trying to backward through the graph a second time occurred because the optimizer's gradients were not being cleared correctly between training batches within the same epoch. The optimizer.zero_grad() call was placed inside the 
        _process_batch
         method, but it should be called once per batch before the loss is calculated and backpropagated. The list comprehension structure in the 
        train_model
         method was also making the control flow less clear.
        
        Recommended Actions
        I will refactor the 
        train_model
         method in 
        a2aNetwork/core/lnnFallback.py
         to:
        
        Use a standard for loop for iterating through training batches, which improves readability.
        Move the optimizer.zero_grad() call to the beginning of the batch processing loop, ensuring gradients are reset before each backpropagation.
        Simplify the loss calculation and accumulation within the loop.
        This change aligns the training loop with standard PyTorch practices and will resolve the RuntimeError. After applying the fix, I will run the tests again to confirm the solution.
        
        lnnFallback.py
        +1
        -2
        Continue response
        
        Continue
        ⌥⏎
        
        Feedback submitted
        
        26m ago
        Aug 21, 11:54 AM
        Me
        
        Continue
        
        Press enter again to interrupt and send a new message
        
        
        
        
        Code
        
        Gemini 2.5 Pro
        ssl_session_tickets off;

        ssl_protocols TLSv1.2 TLSv1.3;
        ssl_ciphers ECDHE-ECDSA-AES128-GCM-SHA256:ECDHE-RSA-AES128-GCM-SHA256:ECDHE-ECDSA-AES256-GCM-SHA384:ECDHE-RSA-AES256-GCM-SHA384;
        ssl_prefer_server_ciphers off;

        # API Gateway - A2A Network
        location /api/ {
            limit_req zone=api burst=20 nodelay;
            proxy_pass http://a2a_network;
            proxy_set_header Host $host;
            proxy_set_header X-Real-IP $remote_addr;
            proxy_set_header X-Forwarded-For $proxy_add_x_forwarded_for;
            proxy_set_header X-Forwarded-Proto $scheme;
            proxy_set_header X-Forwarded-Host $host;
            proxy_set_header X-Forwarded-Port $server_port;
            
            # CORS headers
            add_header Access-Control-Allow-Origin *;
            add_header Access-Control-Allow-Methods "GET, POST, PUT, DELETE, OPTIONS";
            add_header Access-Control-Allow-Headers "Origin, X-Requested-With, Content-Type, Accept, Authorization";
            
            if ($request_method = 'OPTIONS') {
                return 204;
            }
        }

        # Agent Services
        location /agents/ {
            limit_req zone=api burst=15 nodelay;
            proxy_pass http://a2a_agents;
            proxy_set_header Host $host;
            proxy_set_header X-Real-IP $remote_addr;
            proxy_set_header X-Forwarded-For $proxy_add_x_forwarded_for;
            proxy_set_header X-Forwarded-Proto $scheme;
            
            # Health check endpoint
            location /agents/health {
                access_log off;
                proxy_pass http://a2a_agents/health;
            }
        }

        # Registry Service
        location /registry/ {
            limit_req zone=api burst=10 nodelay;
            proxy_pass http://a2a_registry/;
            proxy_set_header Host $host;
            proxy_set_header X-Real-IP $remote_addr;
            proxy_set_header X-Forwarded-For $proxy_add_x_forwarded_for;
            proxy_set_header X-Forwarded-Proto $scheme;
        }

        # Authentication endpoints
        location /auth/ {
            limit_req zone=auth burst=10 nodelay;
            proxy_pass http://a2a_network;
            proxy_set_header Host $host;
            proxy_set_header X-Real-IP $remote_addr;
            proxy_set_header X-Forwarded-For $proxy_add_x_forwarded_for;
            proxy_set_header X-Forwarded-Proto $scheme;
        }

        # Monitoring - Prometheus
        location /prometheus/ {
            auth_basic "Monitoring";
            auth_basic_user_file /etc/nginx/htpasswd;
            proxy_pass http://prometheus:9090/;
            proxy_set_header Host $host;
            proxy_set_header X-Real-IP $remote_addr;
            proxy_set_header X-Forwarded-For $proxy_add_x_forwarded_for;
            proxy_set_header X-Forwarded-Proto $scheme;
        }

        # Monitoring - Grafana
        location /grafana/ {
            proxy_pass http://grafana:3000/;
            proxy_set_header Host $host;
            proxy_set_header X-Real-IP $remote_addr;
            proxy_set_header X-Forwarded-For $proxy_add_x_forwarded_for;
            proxy_set_header X-Forwarded-Proto $scheme;
        }

        # Static files and assets
        location /static/ {
            expires 1y;
            add_header Cache-Control "public, immutable";
            proxy_pass http://a2a_network;
        }

        # WebSocket support
        location /ws/ {
            proxy_pass http://a2a_network;
            proxy_http_version 1.1;
            proxy_set_header Upgrade $http_upgrade;
            proxy_set_header Connection "upgrade";
            proxy_set_header Host $host;
            proxy_set_header X-Real-IP $remote_addr;
            proxy_set_header X-Forwarded-For $proxy_add_x_forwarded_for;
            proxy_set_header X-Forwarded-Proto $scheme;
        }

        # Health check endpoint
        location /health {
            access_log off;
            return 200 "healthy\n";
            add_header Content-Type text/plain;
        }

        # Default location
        location / {
            proxy_pass http://a2a_network;
            proxy_set_header Host $host;
            proxy_set_header X-Real-IP $remote_addr;
            proxy_set_header X-Forwarded-For $proxy_add_x_forwarded_for;
            proxy_set_header X-Forwarded-Proto $scheme;
        }
    }
}